<?xml version="1.0" encoding="utf-8"?>

<sdf version='1.11'>
  <model name='yahboomcar'>
    <link name='base_link'>
      <inertial>
        <pose>0.017942912594123499 -8.3782031781568512e-05 0.081038396600992726 0 0 0</pose>
        <mass>0.74861</mass>
        <inertia>
          <ixx>0.0010564082189183229</ixx>
          <ixy>-1.873423514299318e-06</ixy>
          <ixz>1.6903948178661641e-05</ixz>
          <iyy>0.0030875938519485391</iyy>
          <iyz>3.2317395904979518e-08</iyz>
          <izz>0.0040059345150833918</izz>
        </inertia>
      </inertial>
      <visual name='base_link_visual'>
        <pose>0 0 0 0 0 0</pose>
        <geometry>
          <mesh>
            <scale>1 1 1</scale>
            <uri>package://yahboomcar_description/models/ackermann_r2_car/meshes/base_link.STL</uri>
          </mesh>
        </geometry>
        <material>
          <diffuse>0 0.784312487 0.294112504 1</diffuse>
          <ambient>0 0.784312487 0.294112504 1</ambient>
        </material>
      </visual>
      <collision name='base_link_collision'>
        <pose>0 0 0 0 0 0</pose>
        <geometry>
          <mesh>
            <scale>1 1 1</scale>
            <uri>package://yahboomcar_description/models/ackermann_r2_car/meshes/base_link.STL</uri>
          </mesh>
        </geometry>
      </collision>

      <!-- <visual name='base_link_fixed_joint_lump__camera_link_visual_1'>
        <pose>0.095116999999999993 0 0.09955 0 0.0057171000000000019 0</pose>
        <geometry>
          <mesh>
            <scale>1 1 1</scale>
            <uri>package://yahboomcar_description/models/ackermann_r2_car/meshes/camera_link_R2.STL</uri>
          </mesh>
        </geometry>
        <material>
          <diffuse>0.102941252 0.102941252 0.102941252 1</diffuse>
          <ambient>0.102941252 0.102941252 0.102941252 1</ambient>
        </material>
      </visual>
      <collision name='base_link_fixed_joint_lump__camera_link_collision_1'>
        <pose>0.095116999999999993 0 0.09955 0 0.0057171000000000019 0</pose>
        <geometry>
          <mesh>
            <scale>1 1 1</scale>
            <uri>package://yahboomcar_description/models/ackermann_r2_car/meshes/camera_link_R2.STL</uri>
          </mesh>
        </geometry>
      </collision> -->
      
      <visual name='base_link_fixed_joint_lump__laser_link_visual_2'>
        <pose>0.012548 0 0.1 0 0 0</pose>
        <geometry>
          <mesh>
            <scale>0.001 0.001 0.001</scale>
            <uri>package://yahboomcar_description/models/ackermann_r2_car/meshes/rplidarc1.stl</uri>
          </mesh>
        </geometry>
        <material>
          <diffuse>0.0 0.0 0.0 1</diffuse>
          <ambient>0.0 0.0 0.0 1</ambient>
        </material>
      </visual>
      <collision name='base_link_fixed_joint_lump__laser_link_collision_2'>
        <pose>0.012548 0 0.1 0 0 0</pose>
        <geometry>
          <mesh>
            <scale>0.001 0.001 0.001</scale>
            <uri>package://yahboomcar_description/models/ackermann_r2_car/meshes/rplidarc1.stl</uri>
          </mesh>
        </geometry>
      </collision>

    </link>
    <joint name='back_left_joint' type='revolute'>
      <pose relative_to='base_link'>-0.11607000000000001 0.084250000000000005 0.012500000000000001 0 0 0</pose>
      <parent>base_link</parent>
      <child>back_left_link</child>
      <axis>
        <xyz>0 1 0</xyz>
        <limit>
          <lower>-inf</lower>
          <upper>inf</upper>
        </limit>
        <dynamics>
          <spring_reference>0</spring_reference>
          <spring_stiffness>0</spring_stiffness>
        </dynamics>
      </axis>
    </joint>
    <link name='back_left_link'>
      <pose relative_to='back_left_joint'>0 0 0 0 0 0</pose>
      <inertial>
        <pose>-6.8704271855013501e-08 -0.0015615369007075401 3.00324059371304e-08 0 0 0</pose>
        <mass>0.060236043122063501</mass>
        <inertia>
          <ixx>2.5310098671924401e-05</ixx>
          <ixy>-3.6513870196753597e-11</ixy>
          <ixz>1.1560137411212399e-09</ixz>
          <iyy>4.4343191831587398e-05</iyy>
          <iyz>-7.0198539884028694e-11</iyz>
          <izz>2.53280330627738e-05</izz>
        </inertia>
      </inertial>
      <collision name='back_left_link_collision'>
        <pose>0 0 0 0 0 0</pose>
        <geometry>
          <mesh>
            <scale>1 1 1</scale>
            <uri>package://yahboomcar_description/models/ackermann_r2_car/meshes/back_right_link.STL</uri>
          </mesh>
        </geometry>
      </collision>
      <visual name='back_left_link_visual'>
        <pose>0 0 0 0 0 0</pose>
        <geometry>
          <mesh>
            <scale>1 1 1</scale>
            <uri>package://yahboomcar_description/models/ackermann_r2_car/meshes/back_right_link.STL</uri>
          </mesh>
        </geometry>
        <material>
          <diffuse>0.0 0.0 0.0 1</diffuse>
          <ambient>0.0 0.0 0.0 1</ambient>
        </material>
      </visual>
    </link>
    <joint name='back_right_joint' type='revolute'>
      <pose relative_to='base_link'>-0.11607000000000001 -0.084250000000000005 0.012500000000000001 0 0 0</pose>
      <parent>base_link</parent>
      <child>back_right_link</child>
      <axis>
        <xyz>0 -1 0</xyz>
        <limit>
          <lower>-inf</lower>
          <upper>inf</upper>
        </limit>
        <dynamics>
          <spring_reference>0</spring_reference>
          <spring_stiffness>0</spring_stiffness>
        </dynamics>
      </axis>
    </joint>
    <link name='back_right_link'>
      <pose relative_to='back_right_joint'>0 0 0 0 0 0</pose>
      <inertial>
        <pose>3.8958999999999998e-08 0.0015615 -6.3773999999999999e-08 0 0 0</pose>
        <mass>0.060235999999999998</mass>
        <inertia>
          <ixx>2.5326000000000001e-05</ixx>
          <ixy>-2.7009999999999998e-10</ixy>
          <ixz>3.3546e-09</ixz>
          <iyy>4.4342000000000003e-05</iyy>
          <iyz>-2.9324000000000001e-10</iyz>
          <izz>2.531e-05</izz>
        </inertia>
      </inertial>
      <collision name='back_right_link_collision'>
        <pose>0 0 0 0 0 0</pose>
        <geometry>
          <mesh>
            <scale>1 1 1</scale>
            <uri>package://yahboomcar_description/models/ackermann_r2_car/meshes/back_right_link.STL</uri>
          </mesh>
        </geometry>
      </collision>
      <visual name='back_right_link_visual'>
        <pose>0 0 0 0 0 0</pose>
        <geometry>
          <mesh>
            <scale>1 1 1</scale>
            <uri>package://yahboomcar_description/models/ackermann_r2_car/meshes/back_right_link.STL</uri>
          </mesh>
        </geometry>
        <material>
          <diffuse>0.0 0.0 0.0 1</diffuse>
          <ambient>0.0 0.0 0.0 1</ambient>
        </material>
      </visual>
    </link>
    <joint name='front_left_steer_joint' type='revolute'>
      <pose relative_to='base_link'>0.11922000000000001 0.065000000000000002 0.026200000000000001 0 0 0</pose>
      <parent>base_link</parent>
      <child>front_left_steer</child>
      <axis>
        <xyz>0 0 -1</xyz>
        <limit>
          <lower>0</lower>
          <upper>0</upper>
          <effort>0</effort>
          <velocity>0</velocity>
        </limit>
        <dynamics>
          <spring_reference>0</spring_reference>
          <spring_stiffness>0</spring_stiffness>
        </dynamics>
      </axis>
    </joint>
    <link name='front_left_steer'>
      <pose relative_to='front_left_steer_joint'>0 0 0 0 0 0</pose>
      <inertial>
        <pose>-0.0044676000000000004 0.0031202999999999999 -0.014101000000000001 0 0 0</pose>
        <mass>0.002176</mass>
        <inertia>
          <ixx>1.4000999999999999e-07</ixx>
          <ixy>-7.8357000000000005e-08</ixy>
          <ixz>1.1741e-12</ixz>
          <iyy>2.7800999999999999e-07</iyy>
          <iyz>7.8069000000000006e-12</iyz>
          <izz>2.9089999999999999e-07</izz>
        </inertia>
      </inertial>
      <collision name='front_left_steer_collision'>
        <pose>0 0 0 0 0 0</pose>
        <geometry>
          <mesh>
            <scale>1 1 1</scale>
            <uri>package://yahboomcar_description/models/ackermann_r2_car/meshes/front_left_steer.STL</uri>
          </mesh>
        </geometry>
      </collision>
      <visual name='front_left_steer_visual'>
        <pose>0 0 0 0 0 0</pose>
        <geometry>
          <mesh>
            <scale>1 1 1</scale>
            <uri>package://yahboomcar_description/models/ackermann_r2_car/meshes/front_left_steer.STL</uri>
          </mesh>
        </geometry>
        <material>
          <diffuse>0.102941252 0.700975001 0 1</diffuse>
          <ambient>0.102941252 0.700975001 0 1</ambient>
        </material>
      </visual>
    </link>
    <joint name='front_left_wheel_joint' type='revolute'>
      <pose relative_to='front_left_steer'>0.00022897 0.022800000000000001 -0.0141 0 0 -0.010042000000000002</pose>
      <parent>front_left_steer</parent>
      <child>front_left_wheel</child>
      <axis>
        <xyz>0 -1 0</xyz>
        <limit>
          <lower>-inf</lower>
          <upper>inf</upper>
        </limit>
        <dynamics>
          <spring_reference>0</spring_reference>
          <spring_stiffness>0</spring_stiffness>
        </dynamics>
      </axis>
    </joint>
    <link name='front_left_wheel'>
      <pose relative_to='front_left_wheel_joint'>0 0 0 0 0 0</pose>
      <inertial>
        <pose>-6.1417e-08 -0.0048114999999999998 4.1129999999999998e-08 0 0 0</pose>
        <mass>0.060235999999999998</mass>
        <inertia>
          <ixx>2.531e-05</ixx>
          <ixy>2.9987000000000002e-10</ixy>
          <ixz>3.7780999999999996e-09</ixz>
          <iyy>4.4342000000000003e-05</iyy>
          <iyz>2.6181e-10</iyz>
          <izz>2.5326000000000001e-05</izz>
        </inertia>
      </inertial>
      <collision name='front_left_wheel_collision'>
        <pose>0 0 0 0 0 0</pose>
        <geometry>
          <mesh>
            <scale>1 1 1</scale>
            <uri>package://yahboomcar_description/models/ackermann_r2_car/meshes/back_right_link.STL</uri>
          </mesh>
        </geometry>
      </collision>
      <visual name='front_left_wheel_visual'>
        <pose>0 0 0 0 0 0</pose>
        <geometry>
          <mesh>
            <scale>1 1 1</scale>
            <uri>package://yahboomcar_description/models/ackermann_r2_car/meshes/back_right_link.STL</uri>
          </mesh>
        </geometry>
        <material>
          <diffuse>0.0 0.0 0.0 1</diffuse>
          <ambient>0.0 0.0 0.0 1</ambient>
        </material>
      </visual>
    </link>
    <joint name='front_right_steer_joint' type='revolute'>
      <pose relative_to='base_link'>0.11922000000000001 -0.065000000000000002 0.024199999999999999 0 0 0</pose>
      <parent>base_link</parent>
      <child>front_right_steer</child>
      <axis>
        <xyz>0 0 -1</xyz>
        <limit>
          <lower>0</lower>
          <upper>0</upper>
          <effort>0</effort>
          <velocity>0</velocity>
        </limit>
        <dynamics>
          <spring_reference>0</spring_reference>
          <spring_stiffness>0</spring_stiffness>
        </dynamics>
      </axis>
    </joint>
    <link name='front_right_steer'>
      <pose relative_to='front_right_steer_joint'>0 0 0 0 0 0</pose>
      <inertial>
        <pose>-0.0045386999999999997 -0.0030159000000000002 -0.012099 0 0 0</pose>
        <mass>0.002176</mass>
        <inertia>
          <ixx>1.4371999999999999e-07</ixx>
          <ixy>8.1469e-08</ixy>
          <ixz>-1.0492e-12</ixz>
          <iyy>2.7431000000000003e-07</iyy>
          <iyz>7.8675000000000006e-12</iyz>
          <izz>2.9089999999999999e-07</izz>
        </inertia>
      </inertial>
      <collision name='front_right_steer_collision'>
        <pose>0 0 0 0 0 0</pose>
        <geometry>
          <mesh>
            <scale>1 1 1</scale>
            <uri>package://yahboomcar_description/models/ackermann_r2_car/meshes/front_left_steer.STL</uri>
          </mesh>
        </geometry>
      </collision>
      <visual name='front_right_steer_visual'>
        <pose>0 0 0 0 0 0</pose>
        <geometry>
          <mesh>
            <scale>1 1 1</scale>
            <uri>package://yahboomcar_description/models/ackermann_r2_car/meshes/front_left_steer.STL</uri>
          </mesh>
        </geometry>
        <material>
          <diffuse>0.102941252 0.700975001 0 1</diffuse>
          <ambient>0.102941252 0.700975001 0 1</ambient>
        </material>
      </visual>
    </link>
    <joint name='front_right_wheel_joint' type='revolute'>
      <pose relative_to='front_right_steer'>-0.00025661999999999999 -0.019549 -0.0121 0 0 -0.013126000000000001</pose>
      <parent>front_right_steer</parent>
      <child>front_right_wheel</child>
      <axis>
        <xyz>0 1 0</xyz>
        <limit>
          <lower>-inf</lower>
          <upper>inf</upper>
        </limit>
        <dynamics>
          <spring_reference>0</spring_reference>
          <spring_stiffness>0</spring_stiffness>
        </dynamics>
      </axis>
    </joint>
    <link name='front_right_wheel'>
      <pose relative_to='front_right_wheel_joint'>0 0 0 0 0 0</pose>
      <inertial>
        <pose>5.5753000000000003e-08 0.0015615 -5.0453000000000002e-08 0 0 0</pose>
        <mass>0.060235999999999998</mass>
        <inertia>
          <ixx>2.5324999999999999e-05</ixx>
          <ixy>5.2010000000000003e-11</ixy>
          <ixz>7.1483999999999998e-09</ixz>
          <iyy>4.4342999999999999e-05</iyy>
          <iyz>6.0924000000000003e-11</iyz>
          <izz>2.5313999999999999e-05</izz>
        </inertia>
      </inertial>
      <collision name='front_right_wheel_collision'>
        <pose>0 0 0 0 0 0</pose>
        <geometry>
          <mesh>
            <scale>1 1 1</scale>
            <uri>package://yahboomcar_description/models/ackermann_r2_car/meshes/back_right_link.STL</uri>
          </mesh>
        </geometry>
      </collision>
      <visual name='front_right_wheel_visual'>
        <pose>0 0 0 0 0 0</pose>
        <geometry>
          <mesh>
            <scale>1 1 1</scale>
            <uri>package://yahboomcar_description/models/ackermann_r2_car/meshes/back_right_link.STL</uri>
          </mesh>
        </geometry>
        <material>
          <diffuse>0.0 0.0 0.0 1</diffuse>
          <ambient>0.0 0.0 0.0 1</ambient>
        </material>
      </visual>
    </link>
    <!-- <frame name='camera_joint' attached_to='base_link'>
      <pose>0.095116999999999993 0 0.09955 0 0.0057171000000000027 0</pose>
    </frame>
    <frame name='camera_link' attached_to='camera_joint'>
      <pose>0 0 0 0 0 0</pose>
    </frame> -->
    <frame name='laser_joint' attached_to='base_link'>
      <pose>0.012548 0 0.1 0 0 0</pose>
    </frame>
    <frame name='laser_link' attached_to='laser_joint'>
      <pose>0 0 0 0 0 0</pose>
    </frame>
  </model>
</sdf>
